<?xml version="1.0" ?>
<robot name="humanoid_robot" xmlns:xacro="http://www.ros.org/wiki/xacro">

  <!-- Base Link -->
  <link name="base_link">
    <visual>
      <geometry>
        <box size="0.15 0.15 0.2"/>
      </geometry>
      <material name="gray">
        <color rgba="0.5 0.5 0.5 0.8"/>
      </material>
    </visual>
    <collision>
      <geometry>
        <box size="0.15 0.15 0.2"/>
      </geometry>
    </collision>
    <inertial>
      <mass value="10.0"/>
      <inertia ixx="0.2" ixy="0.0" ixz="0.0" iyy="0.2" iyz="0.0" izz="0.2"/>
    </inertial>
  </link>

  <!-- Torso -->
  <link name="torso">
    <visual>
      <geometry>
        <box size="0.2 0.15 0.3"/>
      </geometry>
      <material name="red">
        <color rgba="1 0 0 0.8"/>
      </material>
    </visual>
    <collision>
      <geometry>
        <box size="0.2 0.15 0.3"/>
      </geometry>
    </collision>
    <inertial>
      <mass value="5.0"/>
      <inertia ixx="0.1" ixy="0.0" ixz="0.0" iyy="0.1" iyz="0.0" izz="0.1"/>
    </inertial>
  </link>

  <!-- Head -->
  <link name="head">
    <visual>
      <geometry>
        <sphere radius="0.1"/>
      </geometry>
      <material name="white">
        <color rgba="1 1 1 0.8"/>
      </material>
    </visual>
    <collision>
      <geometry>
        <sphere radius="0.1"/>
      </geometry>
    </collision>
    <inertial>
      <mass value="2.0"/>
      <inertia ixx="0.02" ixy="0.0" ixz="0.0" iyy="0.02" iyz="0.0" izz="0.02"/>
    </inertial>
  </link>

  <!-- Left Arm Links -->
  <link name="left_shoulder">
    <visual>
      <geometry>
        <cylinder radius="0.05" length="0.15"/>
      </geometry>
      <material name="blue">
        <color rgba="0 0 1 0.8"/>
      </material>
    </visual>
    <collision>
      <geometry>
        <cylinder radius="0.05" length="0.15"/>
      </geometry>
    </collision>
    <inertial>
      <mass value="1.0"/>
      <inertia ixx="0.005" ixy="0.0" ixz="0.0" iyy="0.005" iyz="0.0" izz="0.01"/>
    </inertial>
  </link>

  <link name="left_elbow">
    <visual>
      <geometry>
        <cylinder radius="0.04" length="0.2"/>
      </geometry>
      <material name="blue">
        <color rgba="0 0 1 0.8"/>
      </material>
    </visual>
    <collision>
      <geometry>
        <cylinder radius="0.04" length="0.2"/>
      </geometry>
    </collision>
    <inertial>
      <mass value="0.8"/>
      <inertia ixx="0.004" ixy="0.0" ixz="0.0" iyy="0.004" iyz="0.0" izz="0.016"/>
    </inertial>
  </link>

  <link name="left_hand">
    <visual>
      <geometry>
        <box size="0.1 0.08 0.08"/>
      </geometry>
      <material name="blue">
        <color rgba="0 0 1 0.8"/>
      </material>
    </visual>
    <collision>
      <geometry>
        <box size="0.1 0.08 0.08"/>
      </geometry>
    </collision>
    <inertial>
      <mass value="0.5"/>
      <inertia ixx="0.001" ixy="0.0" ixz="0.0" iyy="0.001" iyz="0.0" izz="0.001"/>
    </inertial>
  </link>

  <!-- Right Arm Links -->
  <link name="right_shoulder">
    <visual>
      <geometry>
        <cylinder radius="0.05" length="0.15"/>
      </geometry>
      <material name="blue">
        <color rgba="0 0 1 0.8"/>
      </material>
    </visual>
    <collision>
      <geometry>
        <cylinder radius="0.05" length="0.15"/>
      </geometry>
    </collision>
    <inertial>
      <mass value="1.0"/>
      <inertia ixx="0.005" ixy="0.0" ixz="0.0" iyy="0.005" iyz="0.0" izz="0.01"/>
    </inertial>
  </link>

  <link name="right_elbow">
    <visual>
      <geometry>
        <cylinder radius="0.04" length="0.2"/>
      </geometry>
      <material name="blue">
        <color rgba="0 0 1 0.8"/>
      </material>
    </visual>
    <collision>
      <geometry>
        <cylinder radius="0.04" length="0.2"/>
      </geometry>
    </collision>
    <inertial>
      <mass value="0.8"/>
      <inertia ixx="0.004" ixy="0.0" ixz="0.0" iyy="0.004" iyz="0.0" izz="0.016"/>
    </inertial>
  </link>

  <link name="right_hand">
    <visual>
      <geometry>
        <box size="0.1 0.08 0.08"/>
      </geometry>
      <material name="blue">
        <color rgba="0 0 1 0.8"/>
      </material>
    </visual>
    <collision>
      <geometry>
        <box size="0.1 0.08 0.08"/>
      </geometry>
    </collision>
    <inertial>
      <mass value="0.5"/>
      <inertia ixx="0.001" ixy="0.0" ixz="0.0" iyy="0.001" iyz="0.0" izz="0.001"/>
    </inertial>
  </link>

  <!-- Left Leg Links -->
  <link name="left_hip">
    <visual>
      <geometry>
        <cylinder radius="0.06" length="0.15"/>
      </geometry>
      <material name="green">
        <color rgba="0 1 0 0.8"/>
      </material>
    </visual>
    <collision>
      <geometry>
        <cylinder radius="0.06" length="0.15"/>
      </geometry>
    </collision>
    <inertial>
      <mass value="1.5"/>
      <inertia ixx="0.01" ixy="0.0" ixz="0.0" iyy="0.01" iyz="0.0" izz="0.02"/>
    </inertial>
  </link>

  <link name="left_knee">
    <visual>
      <geometry>
        <cylinder radius="0.05" length="0.25"/>
      </geometry>
      <material name="green">
        <color rgba="0 1 0 0.8"/>
      </material>
    </visual>
    <collision>
      <geometry>
        <cylinder radius="0.05" length="0.25"/>
      </geometry>
    </collision>
    <inertial>
      <mass value="1.2"/>
      <inertia ixx="0.008" ixy="0.0" ixz="0.0" iyy="0.008" iyz="0.0" izz="0.03"/>
    </inertial>
  </link>

  <link name="left_foot">
    <visual>
      <geometry>
        <box size="0.15 0.08 0.05"/>
      </geometry>
      <material name="green">
        <color rgba="0 1 0 0.8"/>
      </material>
    </visual>
    <collision>
      <geometry>
        <box size="0.15 0.08 0.05"/>
      </geometry>
    </collision>
    <inertial>
      <mass value="0.8"/>
      <inertia ixx="0.002" ixy="0.0" ixz="0.0" iyy="0.002" iyz="0.0" izz="0.002"/>
    </inertial>
  </link>

  <!-- Right Leg Links -->
  <link name="right_hip">
    <visual>
      <geometry>
        <cylinder radius="0.06" length="0.15"/>
      </geometry>
      <material name="green">
        <color rgba="0 1 0 0.8"/>
      </material>
    </visual>
    <collision>
      <geometry>
        <cylinder radius="0.06" length="0.15"/>
      </geometry>
    </collision>
    <inertial>
      <mass value="1.5"/>
      <inertia ixx="0.01" ixy="0.0" ixz="0.0" iyy="0.01" iyz="0.0" izz="0.02"/>
    </inertial>
  </link>

  <link name="right_knee">
    <visual>
      <geometry>
        <cylinder radius="0.05" length="0.25"/>
      </geometry>
      <material name="green">
        <color rgba="0 1 0 0.8"/>
      </material>
    </visual>
    <collision>
      <geometry>
        <cylinder radius="0.05" length="0.25"/>
      </geometry>
    </collision>
    <inertial>
      <mass value="1.2"/>
      <inertia ixx="0.008" ixy="0.0" ixz="0.0" iyy="0.008" iyz="0.0" izz="0.03"/>
    </inertial>
  </link>

  <link name="right_foot">
    <visual>
      <geometry>
        <box size="0.15 0.08 0.05"/>
      </geometry>
      <material name="green">
        <color rgba="0 1 0 0.8"/>
      </material>
    </visual>
    <collision>
      <geometry>
        <box size="0.15 0.08 0.05"/>
      </geometry>
    </collision>
    <inertial>
      <mass value="0.8"/>
      <inertia ixx="0.002" ixy="0.0" ixz="0.0" iyy="0.002" iyz="0.0" izz="0.002"/>
    </inertial>
  </link>

  <!-- Joints -->
  <joint name="torso_joint" type="fixed">
    <parent link="base_link"/>
    <child link="torso"/>
    <origin xyz="0 0 0.25"/>
  </joint>

  <joint name="head_joint" type="revolute">
    <parent link="torso"/>
    <child link="head"/>
    <origin xyz="0 0 0.25"/>
    <axis xyz="0 0 1"/>
    <limit lower="-1.57" upper="1.57" effort="100" velocity="1"/>
  </joint>

  <!-- Left Arm Joints -->
  <joint name="left_shoulder_joint" type="revolute">
    <parent link="torso"/>
    <child link="left_shoulder"/>
    <origin xyz="0.1 0.1 0.1" rpy="0 0 0.785"/>
    <axis xyz="0 0 1"/>
    <limit lower="-1.57" upper="1.57" effort="50" velocity="1"/>
  </joint>

  <joint name="left_elbow_joint" type="revolute">
    <parent link="left_shoulder"/>
    <child link="left_elbow"/>
    <origin xyz="0 0 -0.15" rpy="0 -1.57 0"/>
    <axis xyz="0 1 0"/>
    <limit lower="0" upper="2.35" effort="50" velocity="1"/>
  </joint>

  <joint name="left_hand_joint" type="revolute">
    <parent link="left_elbow"/>
    <child link="left_hand"/>
    <origin xyz="0 0 -0.2" rpy="0 0 0"/>
    <axis xyz="0 0 1"/>
    <limit lower="-1.57" upper="1.57" effort="30" velocity="1"/>
  </joint>

  <!-- Right Arm Joints -->
  <joint name="right_shoulder_joint" type="revolute">
    <parent link="torso"/>
    <child link="right_shoulder"/>
    <origin xyz="0.1 -0.1 0.1" rpy="0 0 -0.785"/>
    <axis xyz="0 0 1"/>
    <limit lower="-1.57" upper="1.57" effort="50" velocity="1"/>
  </joint>

  <joint name="right_elbow_joint" type="revolute">
    <parent link="right_shoulder"/>
    <child link="right_elbow"/>
    <origin xyz="0 0 -0.15" rpy="0 -1.57 0"/>
    <axis xyz="0 1 0"/>
    <limit lower="0" upper="2.35" effort="50" velocity="1"/>
  </joint>

  <joint name="right_hand_joint" type="revolute">
    <parent link="right_elbow"/>
    <child link="right_hand"/>
    <origin xyz="0 0 -0.2" rpy="0 0 0"/>
    <axis xyz="0 0 1"/>
    <limit lower="-1.57" upper="1.57" effort="30" velocity="1"/>
  </joint>

  <!-- Left Leg Joints -->
  <joint name="left_hip_joint" type="revolute">
    <parent link="base_link"/>
    <child link="left_hip"/>
    <origin xyz="-0.075 0.075 -0.1" rpy="0 0 0"/>
    <axis xyz="0 0 1"/>
    <limit lower="-1.57" upper="1.57" effort="100" velocity="1"/>
  </joint>

  <joint name="left_knee_joint" type="revolute">
    <parent link="left_hip"/>
    <child link="left_knee"/>
    <origin xyz="0 0 -0.15" rpy="0 0 0"/>
    <axis xyz="0 1 0"/>
    <limit lower="0" upper="2.35" effort="100" velocity="1"/>
  </joint>

  <joint name="left_foot_joint" type="fixed">
    <parent link="left_knee"/>
    <child link="left_foot"/>
    <origin xyz="0 0 -0.25" rpy="0 0 0"/>
  </joint>

  <!-- Right Leg Joints -->
  <joint name="right_hip_joint" type="revolute">
    <parent link="base_link"/>
    <child link="right_hip"/>
    <origin xyz="-0.075 -0.075 -0.1" rpy="0 0 0"/>
    <axis xyz="0 0 1"/>
    <limit lower="-1.57" upper="1.57" effort="100" velocity="1"/>
  </joint>

  <joint name="right_knee_joint" type="revolute">
    <parent link="right_hip"/>
    <child link="right_knee"/>
    <origin xyz="0 0 -0.15" rpy="0 0 0"/>
    <axis xyz="0 1 0"/>
    <limit lower="0" upper="2.35" effort="100" velocity="1"/>
  </joint>

  <joint name="right_foot_joint" type="fixed">
    <parent link="right_knee"/>
    <child link="right_foot"/>
    <origin xyz="0 0 -0.25" rpy="0 0 0"/>
  </joint>

  <!-- Sensors -->
  <!-- IMU Sensor -->
  <link name="imu_link">
    <visual>
      <geometry>
        <box size="0.01 0.01 0.01"/>
      </geometry>
      <material name="black">
        <color rgba="0 0 0 1"/>
      </material>
    </visual>
    <collision>
      <geometry>
        <box size="0.01 0.01 0.01"/>
      </geometry>
    </collision>
    <inertial>
      <mass value="0.01"/>
      <inertia ixx="0.0001" ixy="0.0" ixz="0.0" iyy="0.0001" iyz="0.0" izz="0.0001"/>
    </inertial>
  </link>

  <joint name="imu_joint" type="fixed">
    <parent link="torso"/>
    <child link="imu_link"/>
    <origin xyz="0 0 0.1"/>
  </joint>

  <!-- Camera Sensor -->
  <link name="camera_link">
    <visual>
      <geometry>
        <box size="0.05 0.05 0.05"/>
      </geometry>
      <material name="black">
        <color rgba="0 0 0 1"/>
      </material>
    </visual>
    <collision>
      <geometry>
        <box size="0.05 0.05 0.05"/>
      </geometry>
    </collision>
    <inertial>
      <mass value="0.1"/>
      <inertia ixx="0.0001" ixy="0.0" ixz="0.0" iyy="0.0001" iyz="0.0" izz="0.0001"/>
    </inertial>
  </link>

  <joint name="camera_joint" type="fixed">
    <parent link="head"/>
    <child link="camera_link"/>
    <origin xyz="0.05 0 0"/>
  </joint>

  <!-- LIDAR Sensor -->
  <link name="lidar_link">
    <visual>
      <geometry>
        <cylinder radius="0.03" length="0.03"/>
      </geometry>
      <material name="black">
        <color rgba="0 0 0 1"/>
      </material>
    </visual>
    <collision>
      <geometry>
        <cylinder radius="0.03" length="0.03"/>
      </geometry>
    </collision>
    <inertial>
      <mass value="0.2"/>
      <inertia ixx="0.0002" ixy="0.0" ixz="0.0" iyy="0.0002" iyz="0.0" izz="0.0004"/>
    </inertial>
  </link>

  <joint name="lidar_joint" type="fixed">
    <parent link="head"/>
    <child link="lidar_link"/>
    <origin xyz="0.05 0 0.05"/>
  </joint>

  <!-- Gazebo Plugins for Sensors -->
  <gazebo reference="imu_link">
    <sensor type="imu" name="imu_sensor">
      <always_on>true</always_on>
      <update_rate>100</update_rate>
      <visualize>true</visualize>
      <imu>
        <angular_velocity>
          <x>
            <noise type="gaussian">
              <mean>0.0</mean>
              <stddev>2e-4</stddev>
            </noise>
          </x>
          <y>
            <noise type="gaussian">
              <mean>0.0</mean>
              <stddev>2e-4</stddev>
            </noise>
          </y>
          <z>
            <noise type="gaussian">
              <mean>0.0</mean>
              <stddev>2e-4</stddev>
            </noise>
          </z>
        </angular_velocity>
        <linear_acceleration>
          <x>
            <noise type="gaussian">
              <mean>0.0</mean>
              <stddev>1.7e-2</stddev>
            </noise>
          </x>
          <y>
            <noise type="gaussian">
              <mean>0.0</mean>
              <stddev>1.7e-2</stddev>
            </noise>
          </y>
          <z>
            <noise type="gaussian">
              <mean>0.0</mean>
              <stddev>1.7e-2</stddev>
            </noise>
          </z>
        </linear_acceleration>
      </imu>
    </sensor>
  </gazebo>

  <gazebo reference="camera_link">
    <sensor type="camera" name="camera_sensor">
      <always_on>true</always_on>
      <update_rate>30</update_rate>
      <camera name="head_camera">
        <horizontal_fov>1.3962634</horizontal_fov>
        <image>
          <width>640</width>
          <height>480</height>
          <format>R8G8B8</format>
        </image>
        <clip>
          <near>0.05</near>
          <far>3</far>
        </clip>
      </camera>
      <plugin name="camera_controller" filename="libgazebo_ros_camera.so">
        <frame_name>camera_link</frame_name>
      </plugin>
    </sensor>
  </gazebo>

  <gazebo reference="lidar_link">
    <sensor type="ray" name="lidar_sensor">
      <always_on>true</always_on>
      <update_rate>10</update_rate>
      <ray>
        <scan>
          <horizontal>
            <samples>360</samples>
            <resolution>1</resolution>
            <min_angle>-3.14159</min_angle>
            <max_angle>3.14159</max_angle>
          </horizontal>
        </scan>
        <range>
          <min>0.1</min>
          <max>10.0</max>
          <resolution>0.01</resolution>
        </range>
      </ray>
      <plugin name="lidar_controller" filename="libgazebo_ros_laser.so">
        <frame_name>lidar_link</frame_name>
      </plugin>
    </sensor>
  </gazebo>

  <!-- Gazebo Materials -->
  <gazebo reference="base_link">
    <material>Gazebo/Grey</material>
  </gazebo>

  <gazebo reference="torso">
    <material>Gazebo/Red</material>
  </gazebo>

  <gazebo reference="head">
    <material>Gazebo/White</material>
  </gazebo>

  <gazebo reference="left_shoulder">
    <material>Gazebo/Blue</material>
  </gazebo>

  <gazebo reference="left_elbow">
    <material>Gazebo/Blue</material>
  </gazebo>

  <gazebo reference="left_hand">
    <material>Gazebo/Blue</material>
  </gazebo>

  <gazebo reference="right_shoulder">
    <material>Gazebo/Blue</material>
  </gazebo>

  <gazebo reference="right_elbow">
    <material>Gazebo/Blue</material>
  </gazebo>

  <gazebo reference="right_hand">
    <material>Gazebo/Blue</material>
  </gazebo>

  <gazebo reference="left_hip">
    <material>Gazebo/Green</material>
  </gazebo>

  <gazebo reference="left_knee">
    <material>Gazebo/Green</material>
  </gazebo>

  <gazebo reference="left_foot">
    <material>Gazebo/Green</material>
  </gazebo>

  <gazebo reference="right_hip">
    <material>Gazebo/Green</material>
  </gazebo>

  <gazebo reference="right_knee">
    <material>Gazebo/Green</material>
  </gazebo>

  <gazebo reference="right_foot">
    <material>Gazebo/Green</material>
  </gazebo>

</robot>